---
title: 'ES6学习笔记(九):Promise'
date: 2016-11-22 11:12:20
tags: ES6 promise
---


### 1从语法上说，Promise是一个对象，从它可以获取异步操作的消息

### 2.Promise对象有以下两个特点。
#### 1)对象的状态不受外界影响。Promise对象代表一个异步操作，有三种状态：Pending（进行中）、Resolved（已完成，又称Fulfilled）和Rejected（已失败）。只有异步操作的结果，可以决定当前是哪一种状态，任何其他操作都无法改变这个状态。这也是Promise这个名字的由来，它的英语意思就是“承诺”，表示其他手段无法改变。
#### 2)一旦状态改变，就不会再变，任何时候都可以得到这个结果。Promise对象的状态改变，只有两种可能：从Pending变为Resolved和从Pending变为Rejected。只要这两种情况发生，状态就凝固了，不会再变了，会一直保持这个结果。就算改变已经发生了，你再对Promise对象添加回调函数，也会立即得到这个结果。这与事件（Event）完全不同，事件的特点是，如果你错过了它，再去监听，是得不到结果的。

### 3.如果Promise状态已经变成Resolved，再抛出错误是无效的。

```
var promise = new Promise(function(resolve, reject) {
  resolve('ok');
  throw new Error('test');
});
promise
  .then(function(value) { console.log(value) })
  .catch(function(error) { console.log(error) });
// ok
```

### 4.跟传统的try/catch代码块不同的是，如果没有使用catch方法指定错误处理的回调函数，Promise对象抛出的错误不会传递到外层代码，即不会有任何反应。

```
var someAsyncThing = function() {
  return new Promise(function(resolve, reject) {
    // 下面一行会报错，因为x没有声明
    resolve(x + 2);
  });
};

someAsyncThing().then(function() {
  console.log('everything is great');
});
```
上面代码中，someAsyncThing函数产生的Promise对象会报错，但是由于没有指定catch方法，这个错误不会被捕获，也不会传递到外层代码，导致运行后没有任何输出。注意，Chrome浏览器不遵守这条规定，它会抛出错误“ReferenceError: x is not defined”。

### 5.Promise.race方法同样是将多个Promise实例，包装成一个新的Promise实例。
```
var p = Promise.race([p1, p2, p3]);
```
上面代码中，只要p1、p2、p3之中有一个实例率先改变状态，p的状态就跟着改变。那个率先改变的 Promise 实例的返回值，就传递给p的回调函数。

### 6.立即resolve的Promise对象，是在本轮“事件循环”（event loop）的结束时，而不是在下一轮“事件循环”的开始时。
```
setTimeout(function () {
  console.log('three');
}, 0);

Promise.resolve().then(function () {
  console.log('two');
});

console.log('one');

// one
// two
// three
```

### 7.Promise.reject()方法的参数，会原封不动地作为reject的理由，变成后续方法的参数。这一点与Promise.resolve方法不一致。
```
const thenable = {
  then(resolve, reject) {
    reject('出错了');
  }
};

Promise.reject(thenable)
.catch(e => {
  console.log(e === thenable)
})
// true
```
上面代码中，Promise.reject方法的参数是一个thenable对象，执行以后，后面catch方法的参数不是reject抛出的“出错了”这个字符串，而是thenable对象。

### 8.done()
```
Promise.prototype.done = function (onFulfilled, onRejected) {
  this.then(onFulfilled, onRejected)
    .catch(function (reason) {
      // 抛出一个全局错误
      setTimeout(() => { throw reason }, 0);
    });
};
```

### 9.finally()
finally方法用于指定不管Promise对象最后状态如何，都会执行的操作。它与done方法的最大区别，它接受一个普通的回调函数作为参数，该函数不管怎样都必须执行。
```
Promise.prototype.finally = function (callback) {
  let P = this.constructor;
  return this.then(
    value  => P.resolve(callback()).then(() => value),
    reason => P.resolve(callback()).then(() => { throw reason })
  );
};
```